[2022-09-19 23:34:30,144] {processor.py:163} INFO - Started process (PID=200) to work on /home/airflow/dags/dag1.py
[2022-09-19 23:34:30,145] {processor.py:642} INFO - Processing file /home/airflow/dags/dag1.py for tasks to queue
[2022-09-19 23:34:30,146] {logging_mixin.py:109} INFO - [2022-09-19 23:34:30,145] {dagbag.py:500} INFO - Filling up the DagBag from /home/airflow/dags/dag1.py
[2022-09-19 23:34:30,151] {logging_mixin.py:109} INFO - [2022-09-19 23:34:30,150] {dagbag.py:334} ERROR - Failed to import: /home/airflow/dags/dag1.py
Traceback (most recent call last):
  File "/usr/local/conda/lib/python3.7/site-packages/airflow/models/dagbag.py", line 331, in _load_modules_from_file
    loader.exec_module(new_module)
  File "<frozen importlib._bootstrap_external>", line 728, in exec_module
  File "<frozen importlib._bootstrap>", line 219, in _call_with_frames_removed
  File "/home/airflow/dags/dag1.py", line 8, in <module>
    "retry_delay":datetime.timedelta(minutes=1),
AttributeError: type object 'datetime.datetime' has no attribute 'timedelta'
[2022-09-19 23:34:30,151] {processor.py:654} WARNING - No viable dags retrieved from /home/airflow/dags/dag1.py
[2022-09-19 23:34:30,165] {processor.py:171} INFO - Processing /home/airflow/dags/dag1.py took 0.023 seconds
[2022-09-19 23:35:25,695] {processor.py:163} INFO - Started process (PID=200) to work on /home/airflow/dags/dag1.py
[2022-09-19 23:35:25,696] {processor.py:642} INFO - Processing file /home/airflow/dags/dag1.py for tasks to queue
[2022-09-19 23:35:25,697] {logging_mixin.py:109} INFO - [2022-09-19 23:35:25,696] {dagbag.py:500} INFO - Filling up the DagBag from /home/airflow/dags/dag1.py
[2022-09-19 23:35:25,701] {logging_mixin.py:109} INFO - [2022-09-19 23:35:25,700] {dagbag.py:334} ERROR - Failed to import: /home/airflow/dags/dag1.py
Traceback (most recent call last):
  File "/usr/local/conda/lib/python3.7/site-packages/airflow/models/dagbag.py", line 331, in _load_modules_from_file
    loader.exec_module(new_module)
  File "<frozen importlib._bootstrap_external>", line 728, in exec_module
  File "<frozen importlib._bootstrap>", line 219, in _call_with_frames_removed
  File "/home/airflow/dags/dag1.py", line 8, in <module>
    "retry_delay":datetime.timedelta(minutes=1),
AttributeError: type object 'datetime.datetime' has no attribute 'timedelta'
[2022-09-19 23:35:25,701] {processor.py:654} WARNING - No viable dags retrieved from /home/airflow/dags/dag1.py
[2022-09-19 23:35:25,714] {processor.py:171} INFO - Processing /home/airflow/dags/dag1.py took 0.021 seconds
[2022-09-19 23:36:16,944] {processor.py:163} INFO - Started process (PID=200) to work on /home/airflow/dags/dag1.py
[2022-09-19 23:36:16,945] {processor.py:642} INFO - Processing file /home/airflow/dags/dag1.py for tasks to queue
[2022-09-19 23:36:16,946] {logging_mixin.py:109} INFO - [2022-09-19 23:36:16,946] {dagbag.py:500} INFO - Filling up the DagBag from /home/airflow/dags/dag1.py
[2022-09-19 23:36:16,949] {logging_mixin.py:109} INFO - [2022-09-19 23:36:16,949] {dagbag.py:334} ERROR - Failed to import: /home/airflow/dags/dag1.py
Traceback (most recent call last):
  File "/usr/local/conda/lib/python3.7/site-packages/airflow/models/dagbag.py", line 331, in _load_modules_from_file
    loader.exec_module(new_module)
  File "<frozen importlib._bootstrap_external>", line 728, in exec_module
  File "<frozen importlib._bootstrap>", line 219, in _call_with_frames_removed
  File "/home/airflow/dags/dag1.py", line 8, in <module>
    "retry_delay":datetime.timedelta(minutes=1),
AttributeError: type object 'datetime.datetime' has no attribute 'timedelta'
[2022-09-19 23:36:16,950] {processor.py:654} WARNING - No viable dags retrieved from /home/airflow/dags/dag1.py
[2022-09-19 23:36:16,962] {processor.py:171} INFO - Processing /home/airflow/dags/dag1.py took 0.021 seconds
